<?xml version="1.0"?>
<sdf version="1.6">
	<model name="my_bot"> 
      <pose>0.0 0.0 0.0 0.0 0.0 0.0</pose>

      <link name="base_footprint"/>

	  <link name="base_link">
	    <inertial>
			<pose>0.0110814300591425 -1.07283050729823E-05 0.17657272751503 0 0 0</pose>
			<mass>13.4817350958382</mass>
			<inertia>
				<ixx>0.314898837628642</ixx>
				<ixy>-1.83915405182082E-05</ixy>
				<ixz>9.71911553669445E-05</ixz>
				<iyy>0.27110302696631</iyy>
				<iyz>-2.51545485645537E-07</iyz>
				<izz>0.545868688934175</izz>
			</inertia>
	    </inertial>
	    <visual name="base_visual">
	      	<pose>0.0 0.0 0.0 0.0 0.0 0.0</pose>
	      	<geometry>
		 		<mesh>
		  			<uri>model://robot/meshes/base_link.STL</uri>
            		<scale>0.001 0.001 0.001</scale>
				</mesh>
	      	</geometry>
	    </visual>
	    <collision name="base_collision">
	       	<pose>0 0 0 0 0 0</pose>
	      	<geometry>
				<mesh>
					<uri>model://robot/meshes/base_link.STL</uri>
					<scale>0.001 0.001 0.001</scale>
				</mesh>
	      	</geometry>
	    </collision>
	  </link>
	  <!-- <joint name="base_joint" type="fixed">
        <parent>base_footprint</parent>
        <child>base_link</child>
        <pose>0.0 0.0 0.0 0 0 0</pose>
      </joint> -->
	  <link name="front_left_wheel">
	    <inertial>
	      	<pose>3.83026943495679E-15 -1.13145603997111E-13 -0.0289999999999808 0 0 0</pose>
			<mass>1.76533942503771</mass>
			<inertia>
				<ixx>0.00818088481028512</ixx>
				<ixy>1.17455235352596E-18</ixy>
				<ixz>5.62382982653917E-20</ixz>
				<iyy>0.00818088481028512</iyy>
				<iyz>2.65575231975444E-17</iyz>
				<izz>0.0158038579869233</izz>
			</inertia>
	    </inertial>
	    <visual name="front_left_wheel_visual">
	       <pose>0.0 0.0 0.0 0.0 0.0 0.0</pose>
	      	<geometry>
				<mesh>
					<uri>model://robot/meshes/front_left_wheel.STL </uri>
					<scale>0.001 0.001 0.001</scale>
				</mesh>
	      	</geometry>
	    </visual>
	    <collision name="front_left_wheel_collision">
	       	<pose>0.0 0.0 0.0 0.0 0.0 0.0</pose>
	      	<geometry>
				<mesh>
					<uri>model://robot/meshes/front_left_wheel.STL </uri>
					<scale>0.001 0.001 0.001</scale>
				</mesh>
	     	 </geometry>
			 <surface>
            <!-- This friction pamareter don't contain reliable data!! -->
            <friction>
              <ode>
                <mu>100000.0</mu>
                <mu2>100000.0</mu2>
                <fdir1>0 0 0</fdir1>
                <slip1>0.0</slip1>
                <slip2>0.0</slip2>
              </ode>
            </friction>
            <contact>
              <ode>
                <soft_cfm>0</soft_cfm>
                <soft_erp>0.2</soft_erp>
                <kp>1e+5</kp>
                <kd>1</kd>
                <max_vel>0.01</max_vel>
                <min_depth>0.001</min_depth>
              </ode>
            </contact>
          </surface>
	    </collision>
	  </link>
	  <joint name="front_left_wheel_joint" type="revolute">
	     	<pose>0.18566 0.37 0.0505 -1.5708 0.0 0.0</pose>
	    	<parent>base_link</parent>
		  	<child>front_left_wheel</child>
			
			<limit
			effort="1"
			velocity="1" />
	  </joint>
	  <link name="front_right_wheel">
	    <inertial>
	       	<pose>0.0 -5.55111512312578E-17 -0.029 0.0 0.0 0.0</pose>
	      
			<mass>1.76533942503771</mass>
			<inertia>
				<ixx>0.00818088481028511</ixx>
				<ixy>1.55583818346496E-18</ixy>
				<ixz>-1.57805560009028E-20</ixz>
				<iyy>0.00818088481028511</iyy>
				<iyz>2.76541224531879E-17</iyz>
				<izz>0.0158038579869233</izz>
			</inertia>
	    </inertial>
	    <visual name="front_right_wheel_visual">
	      	<pose>0.0 0.0 0.0 0.0 0.0 0.0</pose>
	      	<geometry>
				<mesh>
					<uri>model://robot/meshes/front_right_wheel.STL</uri>
					<scale>0.001 0.001 0.001</scale>
				</mesh>
	      	</geometry>
	    </visual>
	    <collision name="front_right_wheel_collision">
	     	<pose>0.0 0.0 0.0 0.0 0.0 0.0</pose>
			<geometry>
				<mesh>
					<uri>model://robot/meshes/front_right_wheel.STL</uri>
					<scale>0.001 0.001 0.001</scale>
				</mesh>
			</geometry>
			<surface>
            <!-- This friction pamareter don't contain reliable data!! -->
            <friction>
              <ode>
                <mu>100000.0</mu>
                <mu2>100000.0</mu2>
                <fdir1>0 0 0</fdir1>
                <slip1>0.0</slip1>
                <slip2>0.0</slip2>
              </ode>
            </friction>
            <contact>
              <ode>
                <soft_cfm>0</soft_cfm>
                <soft_erp>0.2</soft_erp>
                <kp>1e+5</kp>
                <kd>1</kd>
                <max_vel>0.01</max_vel>
                <min_depth>0.001</min_depth>
              </ode>
            </contact>
          </surface>
	    </collision>
	  </link>
	  <joint name="front_right_wheel_joint" type="revolute">
	    	<pose>0.18566 -0.37 0.0505 1.5708 0.0 0.0</pose>
	   	 	<parent>base_link</parent>
			<child>front_right_wheel</child>
			<axis>
				<xyz>0 0 -1</xyz>
			</axis>
			<limit
			effort="1"
			velocity="1" />
	  </joint>
	  <link name="back_right_wheel">
	    <inertial>
			<pose>2.77555756156289E-17 -1.2490009027033E-16 -0.029 0.0 0.0 0.0</pose>
			<mass>1.76533942503771</mass>
			<inertia>
				<ixx>0.00818088481028511</ixx>
				<ixy>-8.31221665572215E-19</ixy>
				<ixz>-1.63529138250933E-19</ixz>
				<iyy>0.00818088481028511</iyy>
				<iyz>5.33492516736472E-17</iyz>
				<izz>0.0158038579869233</izz>
          	</inertia>
	    </inertial>
	    <visual name="back_right_wheel_visual">
			<pose>0.0 0.0 0.0 0.0 0.0 0.0</pose>
			<geometry>
				<mesh>
					<uri>model://robot/meshes/back_right_wheel.STL </uri>
					<scale>0.001 0.001 0.001</scale>
				</mesh>
			</geometry>
	    </visual>
	    <collision name="back_right_wheel_collision">
			<pose>0.0 0.0 0.0 0.0 0.0 0.0</pose>
			<geometry>
				<mesh>
					<uri>model://robot/meshes/back_right_wheel.STL </uri>
					<scale>0.001 0.001 0.001</scale>
				</mesh>
			</geometry>
			<surface>
            <!-- This friction pamareter don't contain reliable data!! -->
            <friction>
              <ode>
                <mu>100000.0</mu>
                <mu2>100000.0</mu2>
                <fdir1>0 0 0</fdir1>
                <slip1>0.0</slip1>
                <slip2>0.0</slip2>
              </ode>
            </friction>
            <contact>
              <ode>
                <soft_cfm>0</soft_cfm>
                <soft_erp>0.2</soft_erp>
                <kp>1e+5</kp>
                <kd>1</kd>
                <max_vel>0.01</max_vel>
                <min_depth>0.001</min_depth>
              </ode>
            </contact>
          </surface>
	    </collision>
	  </link>
	  <joint name="back_right_wheel_joint" type="revolute">
			<pose>-0.18566 -0.37 0.0505 1.5708 0.0 0.0</pose>
			<parent>base_link</parent>
			<child>back_right_wheel</child>
			<axis>
				<xyz>0 0 -1</xyz>
			</axis>
			<limit
			effort="1"
			velocity="1" />
	  </joint>
	  <link name="back_left_wheel">
	    <inertial>
	      	<pose>-2.77555756156289E-17 -1.11022302462516E-16 -0.0289999999999999 0.0 0.0 0.0</pose>
			<mass>1.76533942503771</mass>
			<inertia>
				<ixx>0.00818088481028512</ixx>
				<ixy>8.31221665572211E-19</ixy>
				<ixz>1.55058808778393E-19</ixz>
				<iyy>0.00818088481028512</iyy>
				<iyz>2.65575231975444E-17</iyz>
				<izz>0.0158038579869233</izz>
			</inertia>
	    </inertial>
	    <visual name="back_left_wheel_visual">
			<pose>0.0 0.0 0.0 0.0 0.0 0.0</pose>
			<geometry>
				<mesh>
					<uri>model://robot/meshes/back_left_wheel.STL</uri>
					<scale>0.001 0.001 0.001</scale>
				</mesh>
			</geometry>
	      <!-- <material
		name="">
		<color
		  rgba="0.792156862745098 0.819607843137255 0.933333333333333 1" />
	      </material> -->
	    </visual>
	    <collision name="back_left_wheel_collision">
			<pose>0.0 0.0 0.0 0.0 0.0 0.0</pose>
			<geometry>
				<mesh>
					<uri>model://robot/meshes/back_left_wheel.STL </uri>
					<scale>0.001 0.001 0.001</scale>
				</mesh>
			</geometry>
			<surface>
            <!-- This friction pamareter don't contain reliable data!! -->
            <friction>
              <ode>
                <mu>100000.0</mu>
                <mu2>100000.0</mu2>
                <fdir1>0 0 0</fdir1>
                <slip1>0.0</slip1>
                <slip2>0.0</slip2>
              </ode>
            </friction>
            <contact>
              <ode>
                <soft_cfm>0</soft_cfm>
                <soft_erp>0.2</soft_erp>
                <kp>1e+5</kp>
                <kd>1</kd>
                <max_vel>0.01</max_vel>
                <min_depth>0.001</min_depth>
              </ode>
            </contact>
          </surface>
	    </collision>
	  </link>
	  <joint name="back_left_wheel_joint" type="revolute">
			<pose>-0.18566 0.37 0.0505 0.0 0.0 0.0</pose>
			<parent>base_link</parent>
			<child>back_left_wheel</child>
			<axis>
				<xyz>0 0 -1</xyz>
			</axis>
			<limit
			effort="1"
			velocity="1" />
	  </joint>
	  <link name="laser_frame">
	    <inertial>
			<pose>0.0 0.0 -0.023086642599278 0.0 0.0 0.0</pose>
			<mass>0.221906397086315</mass>
			<inertia>
				<ixx>0.000242495228227766</ixx>
				<ixy>4.65303363426644E-21</ixy>
				<ixz>-3.20040229450624E-20</ixz>
				<iyy>0.000242495228227766</iyy>
				<iyz>6.92322839032914E-22</iyz>
				<izz>0.000357143125094018</izz>
			</inertia>
	    </inertial>
	    <visual name="lidar_sensor_visual">
			<pose>0.0 0.0 0.0 0.0 0.0 0.0 </pose>
			<geometry>
				<mesh>
					<uri>model://robot/meshes/laser_frame.STL </uri>
					<scale>0.001 0.001 0.001</scale>
				</mesh>
			</geometry>
	    </visual>
	    <collision name="lidar_sensor_collision">
			<pose>0.0 0.0 0.0 0.0 0.0 0.0</pose>
			<geometry>
				<mesh>
					<uri>model://robot/meshes/laser_frame.STL</uri>
					<scale>0.001 0.001 0.001</scale>
				</mesh>
			</geometry>
	    </collision>
		<sensor name="hls_lfcd_lds" type="ray">
          <always_on>true</always_on>
          <visualize>false</visualize>
          <pose>-0.064 0 0.15 0 0 0</pose>
          <update_rate>5</update_rate>
          <ray>
            <scan>
              <horizontal>
                <samples>360</samples>
                <resolution>1.000000</resolution>
                <min_angle>0.000000</min_angle>
                <max_angle>6.280000</max_angle>
              </horizontal>
            </scan>
            <range>
              <min>0.00000</min>
              <max>20.0</max>
              <resolution>0.015000</resolution>
            </range>
            <noise>
              <type>gaussian</type>
              <mean>0.0</mean>
              <stddev>0.01</stddev>
            </noise>
          </ray>
          <plugin name="turtlebot3_laserscan" filename="libgazebo_ros_ray_sensor.so">
            <ros>
                <!-- <namespace>/tb3</namespace> -->
                <remapping>~/out:=scan</remapping>
            </ros>
            <output_type>sensor_msgs/LaserScan</output_type>
            <frame_name>laser_frame</frame_name>
          </plugin>
        </sensor>
	  </link>
	  <joint name="laser_joint"
	    type="fixed">
	    <pose>0.0 0.0 0.338 0.0 0.0 0.0</pose>
	    <parent>base_link</parent>
		<child>laser_frame</child>
	    <axis>
	      <xyz>0 0 0</xyz>
        </axis>
	  </joint>
	  
	  <link name="rtk">
	    <inertial>
			<pose>-6.93889390390723E-18 -0.0177792493500667 1.38777878078145E-17 0.0 0.0 0.0</pose>
			<mass>0.125333177215754</mass>
			<inertia>
				<ixx>3.66776232929053E-05</ixx>
				<ixy>-8.99775104438633E-22</ixy>
				<ixz>8.49774290725455E-21</ixz>
				<iyy>7.45130452436299E-05</iyy>
				<iyz>-2.84702837671062E-21</iyz>
				<izz>6.19722649600281E-05</izz>
			</inertia>
	    </inertial>
	    <visual name="rtk_visual">
			<pose>0.0 0.0 0.0 0.0 0.0 0.0</pose>
			<geometry>
				<mesh>
					<uri>model://robot/meshes/rtk.STL </uri>
					<scale>0.001 0.001 0.001</scale>
				</mesh>
			</geometry>
			<!-- <material
				name="">
				<color
			rgba="0.109803921568627 0.109803921568627 0.109803921568627 1" />
			</material> -->
	    </visual>
	    <collision name="rtk_collision">
			<pose>0.0 0.0 0.0 0.0 0.0 0.0</pose>
			<geometry>
				<mesh>
					<uri>model://robot/meshes/rtk.STL</uri>
					<scale>0.001 0.001 0.001</scale>
				</mesh>
			</geometry>
	    </collision>
	  </link>
	  <joint name="rtk_joint" type="fixed">
	    <pose>0.0 0.335 0.193 0.0 0.0 0.0</pose>
	    <parent>base_link</parent>
		<child>rtk</child>
	    <axis>
	      <xyz>0 0 0</xyz>
        </axis>
	  </joint>
	  <plugin name="turtlebot3_joint_state" filename="libgazebo_ros_joint_state_publisher.so">
        <ros>
          <!-- <namespace>/tb3</namespace> -->
            <remapping>~/out:=joint_states</remapping>
        </ros>
        <update_rate>30</update_rate>
		<joint_name>front_left_wheel_joint</joint_name>
        <joint_name>front_right_wheel_joint</joint_name>
        <joint_name>back_left_wheel_joint</joint_name>
        <joint_name>back_right_wheel_joint</joint_name>

      </plugin>
	  <plugin name="skid_steer_drive" filename="libgazebo_ros_diff_drive.so">
         <ros>
          <!-- Set namespace -->
          <!-- <namespace>/demo</namespace> -->

          <!-- Remap default topics -->
          <remapping>cmd_vel:=cmd_vel</remapping>
          <remapping>odom:=odom_demo1</remapping>
		  <remapping>/tf:=tf</remapping>
        </ros>


         <updateRate>100.0</updateRate>
         <robotNamespace>/</robotNamespace>

         <num_wheel_pairs>2</num_wheel_pairs>

         <left_joint>front_left_wheel_joint</left_joint>
         <right_joint>front_right_wheel_joint</right_joint>
         <left_joint>back_left_wheel_joint</left_joint>
         <right_joint>back_right_wheel_joint</right_joint>

         <wheel_separation>0.730</wheel_separation>
         <wheel_separation>0.730</wheel_separation>

         <wheel_diameter>0.25</wheel_diameter>
         <wheel_diameter>0.25</wheel_diameter>

         <max_wheel_torque>5</max_wheel_torque>
         <max_wheel_acceleration>1.0</max_wheel_acceleration>

        <!-- output -->
        <!-- The odom -> base link transform is published by the ekf in robot localization -->
        <publish_odom>true</publish_odom>
        <publish_odom_tf>false</publish_odom_tf>
        <publish_wheel_tf>false</publish_wheel_tf>

        <odometry_topic>odom</odometry_topic>
        <odometry_frame>odom_demo</odometry_frame>
        <robot_base_frame>base_link</robot_base_frame>

      </plugin>
	  
    </model>
</sdf>
