<sdf version='1.7'>
  <model name='my_bot'>
    <link name='base_link'>
      <inertial>
        <pose>0.010803 0.002865 0.178941 0 -0 0</pose>
        <mass>13.829</mass>
        <inertia>
          <ixx>0.33188</ixx>
          <ixy>0.000411165</ixy>
          <ixz>0.000451077</ixz>
          <iyy>0.275665</iyy>
          <iyz>-0.000559536</iyz>
          <izz>0.558828</izz>
        </inertia>
      </inertial>
      <collision name='base_link_collision'>
        <pose>0 0 0 0 -0 0</pose>
        <geometry>
          <mesh>
            <scale>1 1 1</scale>
            <uri>model://robot/meshes/base_link.STL</uri>
          </mesh>
        </geometry>
      </collision>
      <collision name='base_link_fixed_joint_lump__laser_frame_collision_1'>
        <pose>0 0 0.338 0 -0 0</pose>
        <geometry>
          <mesh>
            <scale>1 1 1</scale>
            <uri>model://robot/meshes/laser_frame.STL</uri>
          </mesh>
        </geometry>
      </collision>
      <collision name='base_link_fixed_joint_lump__rtk_collision_2'>
        <pose>0 0.335 0.193 0 -0 0</pose>
        <geometry>
          <mesh>
            <scale>1 1 1</scale>
            <uri>model://robot/meshes/rtk.STL</uri>
          </mesh>
        </geometry>
      </collision>
      <visual name='base_link_visual'>
        <pose>0 0 0 0 -0 0</pose>
        <geometry>
          <mesh>
            <scale>1 1 1</scale>
            <uri>model://robot/meshes/base_link.STL</uri>
          </mesh>
        </geometry>
      </visual>
      <visual name='base_link_fixed_joint_lump__laser_frame_visual_1'>
        <pose>0 0 0.338 0 -0 0</pose>
        <geometry>
          <mesh>
            <scale>1 1 1</scale>
            <uri>model://robot/meshes/laser_frame.STL</uri>
          </mesh>
        </geometry>
      </visual>
      <visual name='base_link_fixed_joint_lump__rtk_visual_2'>
        <pose>0 0.335 0.193 0 -0 0</pose>
        <geometry>
          <mesh>
            <scale>1 1 1</scale>
            <uri>model://robot/meshes/rtk.STL</uri>
          </mesh>
        </geometry>
      </visual>
    </link>
    <joint name='back_left_wheel_joint' type='revolute'>
      <pose relative_to='base_link'>-0.18566 0.37 0.0505 -1.5708 0 0</pose>
      <parent>base_link</parent>
      <child>back_left_wheel</child>
      <axis>
        <xyz>0 0 -1</xyz>
        <limit>
          <effort>1</effort>
          <velocity>1</velocity>
          <lower>-1e+16</lower>
          <upper>1e+16</upper>
        </limit>
        <dynamics>
          <spring_reference>0</spring_reference>
          <spring_stiffness>0</spring_stiffness>
        </dynamics>
      </axis>
    </joint>
    <link name='back_left_wheel'>
      <pose relative_to='back_left_wheel_joint'>0 0 0 0 -0 0</pose>
      <inertial>
        <pose>-0 -0 -0.029 0 -0 0</pose>
        <mass>1.76534</mass>
        <inertia>
          <ixx>0.00818088</ixx>
          <ixy>8.31222e-19</ixy>
          <ixz>1.55059e-19</ixz>
          <iyy>0.00818088</iyy>
          <iyz>2.65575e-17</iyz>
          <izz>0.0158039</izz>
        </inertia>
      </inertial>
      <collision name='back_left_wheel_collision'>
        <pose>0 0 0 0 -0 0</pose>
        <geometry>
          <mesh>
            <scale>1 1 1</scale>
            <uri>model://robot/meshes/back_left_wheel.STL</uri>
          </mesh>
        </geometry>
      </collision>
      <visual name='back_left_wheel_visual'>
        <pose>0 0 0 0 -0 0</pose>
        <geometry>
          <mesh>
            <scale>1 1 1</scale>
            <uri>model://robot/meshes/back_left_wheel.STL</uri>
          </mesh>
        </geometry>
      </visual>
    </link>
    <joint name='back_right_wheel_joint' type='revolute'>
      <pose relative_to='base_link'>-0.18566 -0.37 0.0505 1.5708 -0 0</pose>
      <parent>base_link</parent>
      <child>back_right_wheel</child>
      <axis>
        <xyz>0 0 1</xyz>
        <limit>
          <effort>1</effort>
          <velocity>1</velocity>
          <lower>-1e+16</lower>
          <upper>1e+16</upper>
        </limit>
        <dynamics>
          <spring_reference>0</spring_reference>
          <spring_stiffness>0</spring_stiffness>
        </dynamics>
      </axis>
    </joint>
    <link name='back_right_wheel'>
      <pose relative_to='back_right_wheel_joint'>0 0 0 0 -0 0</pose>
      <inertial>
        <pose>0 -0 -0.029 0 -0 0</pose>
        <mass>1.76534</mass>
        <inertia>
          <ixx>0.00818088</ixx>
          <ixy>-8.31222e-19</ixy>
          <ixz>-1.63529e-19</ixz>
          <iyy>0.00818088</iyy>
          <iyz>5.33493e-17</iyz>
          <izz>0.0158039</izz>
        </inertia>
      </inertial>
      <collision name='back_right_wheel_collision'>
        <pose>0 0 0 0 -0 0</pose>
        <geometry>
          <mesh>
            <scale>1 1 1</scale>
            <uri>model://robot/meshes/back_right_wheel.STL</uri>
          </mesh>
        </geometry>
      </collision>
      <visual name='back_right_wheel_visual'>
        <pose>0 0 0 0 -0 0</pose>
        <geometry>
          <mesh>
            <scale>1 1 1</scale>
            <uri>model://robot/meshes/back_right_wheel.STL</uri>
          </mesh>
        </geometry>
      </visual>
    </link>
    <joint name='front_left_wheel_joint' type='revolute'>
      <pose relative_to='base_link'>0.18566 0.37 0.0505 -1.5708 0 0</pose>
      <parent>base_link</parent>
      <child>front_left_wheel</child>
      <axis>
        <xyz>0 0 -1</xyz>
        <limit>
          <effort>1</effort>
          <velocity>1</velocity>
          <lower>-1e+16</lower>
          <upper>1e+16</upper>
        </limit>
        <dynamics>
          <spring_reference>0</spring_reference>
          <spring_stiffness>0</spring_stiffness>
        </dynamics>
      </axis>
    </joint>
    <link name='front_left_wheel'>
      <pose relative_to='front_left_wheel_joint'>0 0 0 0 -0 0</pose>
      <inertial>
        <pose>0 -0 -0.029 0 -0 0</pose>
        <mass>1.76534</mass>
        <inertia>
          <ixx>0.00818088</ixx>
          <ixy>1.17455e-18</ixy>
          <ixz>5.62383e-20</ixz>
          <iyy>0.00818088</iyy>
          <iyz>2.65575e-17</iyz>
          <izz>0.0158039</izz>
        </inertia>
      </inertial>
      <collision name='front_left_wheel_collision'>
        <pose>0 0 0 0 -0 0</pose>
        <geometry>
          <mesh>
            <scale>1 1 1</scale>
            <uri>model://robot/meshes/front_left_wheel.STL</uri>
          </mesh>
        </geometry>
      </collision>
      <visual name='front_left_wheel_visual'>
        <pose>0 0 0 0 -0 0</pose>
        <geometry>
          <mesh>
            <scale>1 1 1</scale>
            <uri>model://robot/meshes/front_left_wheel.STL</uri>
          </mesh>
        </geometry>
      </visual>
    </link>
    <joint name='front_right_wheel_joint' type='revolute'>
      <pose relative_to='base_link'>0.18566 -0.37 0.0505 1.5708 -0 0</pose>
      <parent>base_link</parent>
      <child>front_right_wheel</child>
      <axis>
        <xyz>0 0 1</xyz>
        <limit>
          <effort>1</effort>
          <velocity>1</velocity>
          <lower>-1e+16</lower>
          <upper>1e+16</upper>
        </limit>
        <dynamics>
          <spring_reference>0</spring_reference>
          <spring_stiffness>0</spring_stiffness>
        </dynamics>
      </axis>
    </joint>
    <link name='front_right_wheel'>
      <pose relative_to='front_right_wheel_joint'>0 0 0 0 -0 0</pose>
      <inertial>
        <pose>0 -0 -0.029 0 -0 0</pose>
        <mass>1.76534</mass>
        <inertia>
          <ixx>0.00818088</ixx>
          <ixy>1.55584e-18</ixy>
          <ixz>-1.57806e-20</ixz>
          <iyy>0.00818088</iyy>
          <iyz>2.76541e-17</iyz>
          <izz>0.0158039</izz>
        </inertia>
      </inertial>
      <collision name='front_right_wheel_collision'>
        <pose>0 0 0 0 -0 0</pose>
        <geometry>
          <mesh>
            <scale>1 1 1</scale>
            <uri>model://robot/meshes/front_right_wheel.STL</uri>
          </mesh>
        </geometry>
      </collision>
      <visual name='front_right_wheel_visual'>
        <pose>0 0 0 0 -0 0</pose>
        <geometry>
          <mesh>
            <scale>1 1 1</scale>
            <uri>model://robot/meshes/front_right_wheel.STL</uri>
          </mesh>
        </geometry>
      </visual>
    </link>
    <plugin name="skid_steer_drive" filename="libgazebo_ros_diff_drive.so">
         <ros>
          <!-- Set namespace -->
          <!-- <namespace>/demo</namespace> -->

          <!-- Remap default topics -->
          <remapping>cmd_vel:=cmd_vel</remapping>
          <remapping>odom:=odom_demo</remapping>
        </ros>


         <updateRate>500.0</updateRate>
         <robotNamespace>/</robotNamespace>

         <num_wheel_pairs>2</num_wheel_pairs>

         <left_joint>front_left_wheel_joint</left_joint>
         <right_joint>front_right_wheel_joint</right_joint>
         <left_joint>back_left_wheel_joint</left_joint>
         <right_joint>back_right_wheel_joint</right_joint>

         <wheel_separation>0.730</wheel_separation>
         <wheel_separation>0.730</wheel_separation>

         <wheel_diameter>0.25</wheel_diameter>
         <wheel_diameter>0.25</wheel_diameter>

         <max_wheel_torque>20</max_wheel_torque>
         <max_wheel_acceleration>1.0</max_wheel_acceleration>

         <publish_odom>true</publish_odom>
        <publish_odom_tf>true</publish_odom_tf>
        <publish_wheel_tf>true</publish_wheel_tf>

        <odometry_frame>odom_demo</odometry_frame>
        <robot_base_frame>base_link</robot_base_frame>

      </plugin>
  </model>
</sdf>
