<?xml version="1.0" encoding="utf-8"?>
<!-- This URDF was automatically created by SolidWorks to URDF Exporter! Originally created by Stephen Brawner (brawner@gmail.com) 
     Commit Version: 1.6.0-4-g7f85cfe  Build Version: 1.6.7995.38578
     For more information, please see http://wiki.ros.org/sw_urdf_exporter -->
<robot
  name="my_bot">
  <link
    name="base_link">
    <inertial>
      <origin
        xyz="0.0110814300591425 -1.07283050729823E-05 0.17657272751503"
        rpy="0 0 0" />
      <mass
        value="13.4817350958382" />
      <inertia
        ixx="0.314898837628642"
        ixy="-1.83915405182082E-05"
        ixz="9.71911553669445E-05"
        iyy="0.27110302696631"
        iyz="-2.51545485645537E-07"
        izz="0.545868688934175" />
    </inertial>
    <visual>
      <origin
        xyz="0 0 0"
        rpy="0 0 0" />
      <geometry>
        <mesh
          filename="file:///home/sunilkumar/dev_ws/src/my_bot/meshes/base_link.STL" />
      </geometry>
      <material
        name="">
        <color
          rgba="0.792156862745098 0.819607843137255 0.933333333333333 1" />
      </material>
    </visual>
    <collision>
      <origin
        xyz="0 0 0"
        rpy="0 0 0" />
      <geometry>
        <mesh
          filename="file:///home/sunilkumar/dev_ws/src/my_bot/meshes/base_link.STL" />
      </geometry>
    </collision>
  </link>
  <link
    name="front_left_wheel">
    <inertial>
      <origin
        xyz="3.83026943495679E-15 -1.13145603997111E-13 -0.0289999999999808"
        rpy="0 0 0" />
      <mass
        value="1.76533942503771" />
      <inertia
        ixx="0.00818088481028512"
        ixy="1.17455235352596E-18"
        ixz="5.62382982653917E-20"
        iyy="0.00818088481028512"
        iyz="2.65575231975444E-17"
        izz="0.0158038579869233" />
    </inertial>
    <visual>
      <origin
        xyz="0 0 0"
        rpy="0 0 0" />
      <geometry>
        <mesh
          filename="file:///home/sunilkumar/dev_ws/src/my_bot/meshes/front_left_wheel.STL" />
      </geometry>
      <material
        name="">
        <color
          rgba="0.792156862745098 0.819607843137255 0.933333333333333 1" />
      </material>
    </visual>
    <collision>
      <origin
        xyz="0 0 0"
        rpy="0 0 0" />
      <geometry>
        <mesh
          filename="file:///home/sunilkumar/dev_ws/src/my_bot/meshes/front_left_wheel.STL" />
      </geometry>
    </collision>
  </link>
  <joint
    name="front_left_wheel_joint"
    type="continuous">
    <origin
      xyz="0.18566 0.37 0.0505"
      rpy="-1.5708 0 0" />
    <parent
      link="base_link" />
    <child
      link="front_left_wheel" />
    <axis
      xyz="0 0 -1" />
    <limit
      effort="1"
      velocity="1" />
  </joint>
  <link
    name="front_right_wheel">
    <inertial>
      <origin
        xyz="0 -5.55111512312578E-17 -0.029"
        rpy="0 0 0" />
      <mass
        value="1.76533942503771" />
      <inertia
        ixx="0.00818088481028511"
        ixy="1.55583818346496E-18"
        ixz="-1.57805560009028E-20"
        iyy="0.00818088481028511"
        iyz="2.76541224531879E-17"
        izz="0.0158038579869233" />
    </inertial>
    <visual>
      <origin
        xyz="0 0 0"
        rpy="0 0 0" />
      <geometry>
        <mesh
          filename="file:///home/sunilkumar/dev_ws/src/my_bot/meshes/front_right_wheel.STL" />
      </geometry>
      <material
        name="">
        <color
          rgba="0.792156862745098 0.819607843137255 0.933333333333333 1" />
      </material>
    </visual>
    <collision>
      <origin
        xyz="0 0 0"
        rpy="0 0 0" />
      <geometry>
        <mesh
          filename="file:///home/sunilkumar/dev_ws/src/my_bot/meshes/front_right_wheel.STL" />
      </geometry>
    </collision>
  </link>
  <joint
    name="front_right_wheel_joint"
    type="continuous">
    <origin
      xyz="0.18566 -0.37 0.0505"
      rpy="1.5708 0 0" />
    <parent
      link="base_link" />
    <child
      link="front_right_wheel" />
    <axis
      xyz="0 0 -1" />
    <limit
      effort="1"
      velocity="1" />
  </joint>
  <link
    name="back_right_wheel">
    <inertial>
      <origin
        xyz="2.77555756156289E-17 -1.2490009027033E-16 -0.029"
        rpy="0 0 0" />
      <mass
        value="1.76533942503771" />
      <inertia
        ixx="0.00818088481028511"
        ixy="-8.31221665572215E-19"
        ixz="-1.63529138250933E-19"
        iyy="0.00818088481028511"
        iyz="5.33492516736472E-17"
        izz="0.0158038579869233" />
    </inertial>
    <visual>
      <origin
        xyz="0 0 0"
        rpy="0 0 0" />
      <geometry>
        <mesh
          filename="file:///home/sunilkumar/dev_ws/src/my_bot/meshes/back_right_wheel.STL" />
      </geometry>
      <material
        name="">
        <color
          rgba="0.792156862745098 0.819607843137255 0.933333333333333 1" />
      </material>
    </visual>
    <collision>
      <origin
        xyz="0 0 0"
        rpy="0 0 0" />
      <geometry>
        <mesh
          filename="file:///home/sunilkumar/dev_ws/src/my_bot/meshes/back_right_wheel.STL" />
      </geometry>
    </collision>
  </link>
  <joint
    name="back_right_wheel_joint"
    type="continuous">
    <origin
      xyz="-0.18566 -0.37 0.0505"
      rpy="1.5708 0 0" />
    <parent
      link="base_link" />
    <child
      link="back_right_wheel" />
    <axis
      xyz="0 0 -1" />
    <limit
      effort="1"
      velocity="1" />
  </joint>
  <link
    name="back_left_wheel">
    <inertial>
      <origin
        xyz="-2.77555756156289E-17 -1.11022302462516E-16 -0.0289999999999999"
        rpy="0 0 0" />
      <mass
        value="1.76533942503771" />
      <inertia
        ixx="0.00818088481028512"
        ixy="8.31221665572211E-19"
        ixz="1.55058808778393E-19"
        iyy="0.00818088481028512"
        iyz="2.65575231975444E-17"
        izz="0.0158038579869233" />
    </inertial>
    <visual>
      <origin
        xyz="0 0 0"
        rpy="0 0 0" />
      <geometry>
        <mesh
          filename="file:///home/sunilkumar/dev_ws/src/my_bot/meshes/back_left_wheel.STL" />
      </geometry>
      <material
        name="">
        <color
          rgba="0.792156862745098 0.819607843137255 0.933333333333333 1" />
      </material>
    </visual>
    <collision>
      <origin
        xyz="0 0 0"
        rpy="0 0 0" />
      <geometry>
        <mesh
          filename="file:///home/sunilkumar/dev_ws/src/my_bot/meshes/back_left_wheel.STL" />
      </geometry>
    </collision>
  </link>
  <joint
    name="back_left_wheel_joint"
    type="continuous">
    <origin
      xyz="-0.18566 0.37 0.0505"
      rpy="-1.5708 0 0" />
    <parent
      link="base_link" />
    <child
      link="back_left_wheel" />
    <axis
      xyz="0 0 -1" />
    <limit
      effort="1"
      velocity="1" />
  </joint>
  <link
    name="laser_frame">
    <inertial>
      <origin
        xyz="0 0 -0.023086642599278"
        rpy="0 0 0" />
      <mass
        value="0.221906397086315" />
      <inertia
        ixx="0.000242495228227766"
        ixy="4.65303363426644E-21"
        ixz="-3.20040229450624E-20"
        iyy="0.000242495228227766"
        iyz="6.92322839032914E-22"
        izz="0.000357143125094018" />
    </inertial>
    <visual>
      <origin
        xyz="0 0 0"
        rpy="0 0 0" />
      <geometry>
        <mesh
          filename="file:///home/sunilkumar/dev_ws/src/my_bot/meshes/laser_frame.STL" />
      </geometry>
      <material
        name="">
        <color
          rgba="1 1 1 1" />
      </material>
    </visual>
    <collision>
      <origin
        xyz="0 0 0"
        rpy="0 0 0" />
      <geometry>
        <mesh
          filename="file:///home/sunilkumar/dev_ws/src/my_bot/meshes/laser_frame.STL" />
      </geometry>
    </collision>
  </link>
  <joint
    name="laser_joint"
    type="fixed">
    <origin
      xyz="0 0 0.338"
      rpy="0 0 0" />
    <parent
      link="base_link" />
    <child
      link="laser_frame" />
    <axis
      xyz="0 0 0" />
  </joint>
  <link
    name="rtk">
    <inertial>
      <origin
        xyz="-6.93889390390723E-18 -0.0177792493500667 1.38777878078145E-17"
        rpy="0 0 0" />
      <mass
        value="0.125333177215754" />
      <inertia
        ixx="3.66776232929053E-05"
        ixy="-8.99775104438633E-22"
        ixz="8.49774290725455E-21"
        iyy="7.45130452436299E-05"
        iyz="-2.84702837671062E-21"
        izz="6.19722649600281E-05" />
    </inertial>
    <visual>
      <origin
        xyz="0 0 0"
        rpy="0 0 0" />
      <geometry>
        <mesh
          filename="file:///home/sunilkumar/dev_ws/src/my_bot/meshes/rtk.STL" />
      </geometry>
      <material
        name="">
        <color
          rgba="0.109803921568627 0.109803921568627 0.109803921568627 1" />
      </material>
    </visual>
    <collision>
      <origin
        xyz="0 0 0"
        rpy="0 0 0" />
      <geometry>
        <mesh
          filename="file:///home/sunilkumar/dev_ws/src/my_bot/meshes/rtk.STL" />
      </geometry>
    </collision>
  </link>
  <joint
    name="rtk_joint"
    type="fixed">
    <origin
      xyz="0 0.335 0.193"
      rpy="0 0 0" />
    <parent
      link="base_link" />
    <child
      link="rtk" />
    <axis
      xyz="0 0 0" />
  </joint>
</robot>